Workbook

Sheet Estructura
B2: id | C2: dimension | D2: subdimension | E2: categoria | F2: recomendacion | G2: ejemplo | H2: texto_embedding | I2: dimension_id | J2: subdimension_id | K2: categoria_id
B3: =+Tabla1[[#This Row],[dimension_id]]&"_"&Tabla1[[#This Row],[subdimension_id]]&"_"&Tabla1[[#This Row],[categoria_id]] -> DI_OM_cat | C3: Didáctica inclusiva | D3: Objetivos y metas | F3: Proporcione información sobre los objetivos y metas de aprendizaje en la portada del recurso. Asegúrese de que todos los objetivos de aprendizaje sean alcanzables, mensurables, relevantes, claramente enunciados y concisos para los estudiantes y otros docentes que utilicen sus REA. | H3: =+"Dimensión: " & Tabla1[[#This Row],[dimension]] & " -- " & "Subdimensión: " & Tabla1[[#This Row],[subdimension]] & " -- " & "Categoría: " & Tabla1[[#This Row],[categoria]] & " -- " & Tabla1[[#This Row],[recomendacion]] -> Dimensión: Didáctica inclusiva -- Subdimensión: Objetivos y metas -- Categoría: -- Proporcione información sobre los objetivos y metas de aprendizaje en la portada del recurso. Asegúrese de que todos los objetivos de aprendizaje sean alcanzables, mensurables, relevantes, claramente enunciados y concisos para los estudiantes y otros docentes que utilicen sus REA. | I3: =IFERROR(VLOOKUP(Tabla1[[#This Row],[dimension]],Datos!$B$2:$C$6,2,0),"dim") -> DI | J3: =IFERROR(VLOOKUP(Tabla1[[#This Row],[subdimension]],Datos!$E$2:$F$20,2,0),"subdim") -> OM | K3: =IFERROR(VLOOKUP(Tabla1[[#This Row],[categoria]],Datos!$H$2:$I$21,2,0),"cat") -> cat
B4: =+Tabla1[[#This Row],[dimension_id]]&"_"&Tabla1[[#This Row],[subdimension_id]]&"_"&Tabla1[[#This Row],[categoria_id]] -> DI_OA_cat | C4: Didáctica inclusiva | D4: Objetivos de aprendizaje para la enseñanza diferenciada | F4: Personalice, ajuste y adapte sus REA para obtener resultados de aprendizaje óptimos, que pueden no ser los mismos para todos. Asegúrese de que los objetivos y contenidos de un REA se basen en la edad y el nivel de competencia inicial de los estudiantes. | G4: Determine objetivos de aprendizaje individualizados; haga que el contenido de los REA sea accesible según las diferentes necesidades de aprendizaje de los estudiantes con y sin discapacidades. Si un REA está diseñado para niños pequeños, debe tener contenido visual adaptado a ellos, como dibujos y textos más sencillos. Si el mismo REA está destinado a niños mayores, debe incluir menos contenido visual y más contenido para adultos, como fotografías. El texto puede requerir un nivel de lectura más alto. | H4: =+"Dimensión: " & Tabla1[[#This Row],[dimension]] & " -- " & "Subdimensión: " & Tabla1[[#This Row],[subdimension]] & " -- " & "Categoría: " & Tabla1[[#This Row],[categoria]] & " -- " & Tabla1[[#This Row],[recomendacion]] -> Dimensión: Didáctica inclusiva -- Subdimensión: Objetivos de aprendizaje para la enseñanza diferenciada -- Categoría: -- Personalice, ajuste y adapte sus REA para obtener resultados de aprendizaje óptimos, que pueden no ser los mismos para todos. Asegúrese de que los objetivos y contenidos de un REA se basen en la edad y el nivel de competencia inicial de los estudiantes. | I4: =IFERROR(VLOOKUP(Tabla1[[#This Row],[dimension]],Datos!$B$2:$C$6,2,0),"dim") -> DI | J4: =IFERROR(VLOOKUP(Tabla1[[#This Row],[subdimension]],Datos!$E$2:$F$20,2,0),"subdim") -> OA | K4: =IFERROR(VLOOKUP(Tabla1[[#This Row],[categoria]],Datos!$H$2:$I$21,2,0),"cat") -> cat
B5: =+Tabla1[[#This Row],[dimension_id]]&"_"&Tabla1[[#This Row],[subdimension_id]]&"_"&Tabla1[[#This Row],[categoria_id]] -> DI_OA_cat | C5: Didáctica inclusiva | D5: Objetivos de aprendizaje para la enseñanza diferenciada | F5: Al crear o utilizar REA, tenga en cuenta las necesidades de sus estudiantes (incluidos los estudiantes con discapacidades y necesidades educativas específicas, así como los estudiantes de alto rendimiento), especialmente en el diseño y la metodología de los REA. Considerar las necesidades de los estudiantes desde el principio puede evitar la realización de adaptaciones posteriores. | G5: Intente desarrollar una única versión accesible para todos los estudiantes, considerando su diversidad. De lo contrario, cree versiones diferenciadas adaptadas a sus necesidades. | H5: =+"Dimensión: " & Tabla1[[#This Row],[dimension]] & " -- " & "Subdimensión: " & Tabla1[[#This Row],[subdimension]] & " -- " & "Categoría: " & Tabla1[[#This Row],[categoria]] & " -- " & Tabla1[[#This Row],[recomendacion]] -> Dimensión: Didáctica inclusiva -- Subdimensión: Objetivos de aprendizaje para la enseñanza diferenciada -- Categoría: -- Al crear o utilizar REA, tenga en cuenta las necesidades de sus estudiantes (incluidos los estudiantes con discapacidades y necesidades educativas específicas, así como los estudiantes de alto rendimiento), especialmente en el diseño y la metodología de los REA. Considerar las necesidades de los estudiantes desde el principio puede evitar la realización de adaptaciones posteriores. | I5: =IFERROR(VLOOKUP(Tabla1[[#This Row],[dimension]],Datos!$B$2:$C$6,2,0),"dim") -> DI | J5: =IFERROR(VLOOKUP(Tabla1[[#This Row],[subdimension]],Datos!$E$2:$F$20,2,0),"subdim") -> OA | K5: =IFERROR(VLOOKUP(Tabla1[[#This Row],[categoria]],Datos!$H$2:$I$21,2,0),"cat") -> cat
B6: =+Tabla1[[#This Row],[dimension_id]]&"_"&Tabla1[[#This Row],[subdimension_id]]&"_"&Tabla1[[#This Row],[categoria_id]] -> DI_MD_cat | C6: Didáctica inclusiva | D6: Metadatos | F6: Incluya instrucciones para las actividades de aprendizaje y explique las metodologías. | H6: =+"Dimensión: " & Tabla1[[#This Row],[dimension]] & " -- " & "Subdimensión: " & Tabla1[[#This Row],[subdimension]] & " -- " & "Categoría: " & Tabla1[[#This Row],[categoria]] & " -- " & Tabla1[[#This Row],[recomendacion]] -> Dimensión: Didáctica inclusiva -- Subdimensión: Metadatos -- Categoría: -- Incluya instrucciones para las actividades de aprendizaje y explique las metodologías. | I6: =IFERROR(VLOOKUP(Tabla1[[#This Row],[dimension]],Datos!$B$2:$C$6,2,0),"dim") -> DI | J6: =IFERROR(VLOOKUP(Tabla1[[#This Row],[subdimension]],Datos!$E$2:$F$20,2,0),"subdim") -> MD | K6: =IFERROR(VLOOKUP(Tabla1[[#This Row],[categoria]],Datos!$H$2:$I$21,2,0),"cat") -> cat
B7: =+Tabla1[[#This Row],[dimension_id]]&"_"&Tabla1[[#This Row],[subdimension_id]]&"_"&Tabla1[[#This Row],[categoria_id]] -> DI_MD_cat | C7: Didáctica inclusiva | D7: Metadatos | F7: Indique para qué grupo objetivo de estudiantes se ha creado el recurso, así como los conocimientos previos necesarios. | H7: =+"Dimensión: " & Tabla1[[#This Row],[dimension]] & " -- " & "Subdimensión: " & Tabla1[[#This Row],[subdimension]] & " -- " & "Categoría: " & Tabla1[[#This Row],[categoria]] & " -- " & Tabla1[[#This Row],[recomendacion]] -> Dimensión: Didáctica inclusiva -- Subdimensión: Metadatos -- Categoría: -- Indique para qué grupo objetivo de estudiantes se ha creado el recurso, así como los conocimientos previos necesarios. | I7: =IFERROR(VLOOKUP(Tabla1[[#This Row],[dimension]],Datos!$B$2:$C$6,2,0),"dim") -> DI | J7: =IFERROR(VLOOKUP(Tabla1[[#This Row],[subdimension]],Datos!$E$2:$F$20,2,0),"subdim") -> MD | K7: =IFERROR(VLOOKUP(Tabla1[[#This Row],[categoria]],Datos!$H$2:$I$21,2,0),"cat") -> cat
B8: =+Tabla1[[#This Row],[dimension_id]]&"_"&Tabla1[[#This Row],[subdimension_id]]&"_"&Tabla1[[#This Row],[categoria_id]] -> DI_MD_cat | C8: Didáctica inclusiva | D8: Metadatos | F8: Tenga en cuenta el tiempo estimado necesario para completar el material (hojas de ejercicios o planes de lecciones) (y prepare material y actividades adicionales para los estudiantes más rápidos). | H8: =+"Dimensión: " & Tabla1[[#This Row],[dimension]] & " -- " & "Subdimensión: " & Tabla1[[#This Row],[subdimension]] & " -- " & "Categoría: " & Tabla1[[#This Row],[categoria]] & " -- " & Tabla1[[#This Row],[recomendacion]] -> Dimensión: Didáctica inclusiva -- Subdimensión: Metadatos -- Categoría: -- Tenga en cuenta el tiempo estimado necesario para completar el material (hojas de ejercicios o planes de lecciones) (y prepare material y actividades adicionales para los estudiantes más rápidos). | I8: =IFERROR(VLOOKUP(Tabla1[[#This Row],[dimension]],Datos!$B$2:$C$6,2,0),"dim") -> DI | J8: =IFERROR(VLOOKUP(Tabla1[[#This Row],[subdimension]],Datos!$E$2:$F$20,2,0),"subdim") -> MD | K8: =IFERROR(VLOOKUP(Tabla1[[#This Row],[categoria]],Datos!$H$2:$I$21,2,0),"cat") -> cat
B9: =+Tabla1[[#This Row],[dimension_id]]&"_"&Tabla1[[#This Row],[subdimension_id]]&"_"&Tabla1[[#This Row],[categoria_id]] -> DI_MD_cat | C9: Didáctica inclusiva | D9: Metadatos | F9: Asegúrese de que los ejercicios y actividades estén respaldados por claves de respuestas o pautas de puntuación. | H9: =+"Dimensión: " & Tabla1[[#This Row],[dimension]] & " -- " & "Subdimensión: " & Tabla1[[#This Row],[subdimension]] & " -- " & "Categoría: " & Tabla1[[#This Row],[categoria]] & " -- " & Tabla1[[#This Row],[recomendacion]] -> Dimensión: Didáctica inclusiva -- Subdimensión: Metadatos -- Categoría: -- Asegúrese de que los ejercicios y actividades estén respaldados por claves de respuestas o pautas de puntuación. | I9: =IFERROR(VLOOKUP(Tabla1[[#This Row],[dimension]],Datos!$B$2:$C$6,2,0),"dim") -> DI | J9: =IFERROR(VLOOKUP(Tabla1[[#This Row],[subdimension]],Datos!$E$2:$F$20,2,0),"subdim") -> MD | K9: =IFERROR(VLOOKUP(Tabla1[[#This Row],[categoria]],Datos!$H$2:$I$21,2,0),"cat") -> cat
B10: =+Tabla1[[#This Row],[dimension_id]]&"_"&Tabla1[[#This Row],[subdimension_id]]&"_"&Tabla1[[#This Row],[categoria_id]] -> DI_IDI_cat | C10: Didáctica inclusiva | D10: Idioma | F10: Asegúrese de que el lenguaje sea claro, coherente, conciso y fácilmente comprensible para otros docentes y profesionales del ámbito educativo. | H10: =+"Dimensión: " & Tabla1[[#This Row],[dimension]] & " -- " & "Subdimensión: " & Tabla1[[#This Row],[subdimension]] & " -- " & "Categoría: " & Tabla1[[#This Row],[categoria]] & " -- " & Tabla1[[#This Row],[recomendacion]] -> Dimensión: Didáctica inclusiva -- Subdimensión: Idioma -- Categoría: -- Asegúrese de que el lenguaje sea claro, coherente, conciso y fácilmente comprensible para otros docentes y profesionales del ámbito educativo. | I10: =IFERROR(VLOOKUP(Tabla1[[#This Row],[dimension]],Datos!$B$2:$C$6,2,0),"dim") -> DI | J10: =IFERROR(VLOOKUP(Tabla1[[#This Row],[subdimension]],Datos!$E$2:$F$20,2,0),"subdim") -> IDI | K10: =IFERROR(VLOOKUP(Tabla1[[#This Row],[categoria]],Datos!$H$2:$I$21,2,0),"cat") -> cat
B11: =+Tabla1[[#This Row],[dimension_id]]&"_"&Tabla1[[#This Row],[subdimension_id]]&"_"&Tabla1[[#This Row],[categoria_id]] -> DI_CT_cat | C11: Didáctica inclusiva | D11: Actualización | F11: Asegúrese de que el contenido sea actual, actualizado o atemporal. Si es necesario, actualícelo. | H11: =+"Dimensión: " & Tabla1[[#This Row],[dimension]] & " -- " & "Subdimensión: " & Tabla1[[#This Row],[subdimension]] & " -- " & "Categoría: " & Tabla1[[#This Row],[categoria]] & " -- " & Tabla1[[#This Row],[recomendacion]] -> Dimensión: Didáctica inclusiva -- Subdimensión: Actualización -- Categoría: -- Asegúrese de que el contenido sea actual, actualizado o atemporal. Si es necesario, actualícelo. | I11: =IFERROR(VLOOKUP(Tabla1[[#This Row],[dimension]],Datos!$B$2:$C$6,2,0),"dim") -> DI | J11: =IFERROR(VLOOKUP(Tabla1[[#This Row],[subdimension]],Datos!$E$2:$F$20,2,0),"subdim") -> CT | K11: =IFERROR(VLOOKUP(Tabla1[[#This Row],[categoria]],Datos!$H$2:$I$21,2,0),"cat") -> cat
B12: =+Tabla1[[#This Row],[dimension_id]]&"_"&Tabla1[[#This Row],[subdimension_id]]&"_"&Tabla1[[#This Row],[categoria_id]] -> DI_ES_cat | C12: Didáctica inclusiva | D12: Estructura | F12: Asegúrese de que los REA proporcionen una estructura sólida para el desarrollo de conocimientos y habilidades. Por lo tanto, el contenido debe estructurarse en secuencias lógicas y manejables de módulos o lecciones/secciones. | H12: =+"Dimensión: " & Tabla1[[#This Row],[dimension]] & " -- " & "Subdimensión: " & Tabla1[[#This Row],[subdimension]] & " -- " & "Categoría: " & Tabla1[[#This Row],[categoria]] & " -- " & Tabla1[[#This Row],[recomendacion]] -> Dimensión: Didáctica inclusiva -- Subdimensión: Estructura -- Categoría: -- Asegúrese de que los REA proporcionen una estructura sólida para el desarrollo de conocimientos y habilidades. Por lo tanto, el contenido debe estructurarse en secuencias lógicas y manejables de módulos o lecciones/secciones. | I12: =IFERROR(VLOOKUP(Tabla1[[#This Row],[dimension]],Datos!$B$2:$C$6,2,0),"dim") -> DI | J12: =IFERROR(VLOOKUP(Tabla1[[#This Row],[subdimension]],Datos!$E$2:$F$20,2,0),"subdim") -> ES | K12: =IFERROR(VLOOKUP(Tabla1[[#This Row],[categoria]],Datos!$H$2:$I$21,2,0),"cat") -> cat
B13: =+Tabla1[[#This Row],[dimension_id]]&"_"&Tabla1[[#This Row],[subdimension_id]]&"_"&Tabla1[[#This Row],[categoria_id]] -> DI_DD_cat | C13: Didáctica inclusiva | D13: Didáctica | F13: Vincule el contenido nuevo con los conocimientos, habilidades y experiencias previas de los estudiantes. | H13: =+"Dimensión: " & Tabla1[[#This Row],[dimension]] & " -- " & "Subdimensión: " & Tabla1[[#This Row],[subdimension]] & " -- " & "Categoría: " & Tabla1[[#This Row],[categoria]] & " -- " & Tabla1[[#This Row],[recomendacion]] -> Dimensión: Didáctica inclusiva -- Subdimensión: Didáctica -- Categoría: -- Vincule el contenido nuevo con los conocimientos, habilidades y experiencias previas de los estudiantes. | I13: =IFERROR(VLOOKUP(Tabla1[[#This Row],[dimension]],Datos!$B$2:$C$6,2,0),"dim") -> DI | J13: =IFERROR(VLOOKUP(Tabla1[[#This Row],[subdimension]],Datos!$E$2:$F$20,2,0),"subdim") -> DD | K13: =IFERROR(VLOOKUP(Tabla1[[#This Row],[categoria]],Datos!$H$2:$I$21,2,0),"cat") -> cat
B14: =+Tabla1[[#This Row],[dimension_id]]&"_"&Tabla1[[#This Row],[subdimension_id]]&"_"&Tabla1[[#This Row],[categoria_id]] -> DI_DD_cat | C14: Didáctica inclusiva | D14: Didáctica | F14: Debe asegurar que los REA posibiliten la transferencia de nuevos conocimientos y habilidades a diferentes tareas, problemas o contextos para consolidar su aprendizaje o construir significado personal. | H14: =+"Dimensión: " & Tabla1[[#This Row],[dimension]] & " -- " & "Subdimensión: " & Tabla1[[#This Row],[subdimension]] & " -- " & "Categoría: " & Tabla1[[#This Row],[categoria]] & " -- " & Tabla1[[#This Row],[recomendacion]] -> Dimensión: Didáctica inclusiva -- Subdimensión: Didáctica -- Categoría: -- Debe asegurar que los REA posibiliten la transferencia de nuevos conocimientos y habilidades a diferentes tareas, problemas o contextos para consolidar su aprendizaje o construir significado personal. | I14: =IFERROR(VLOOKUP(Tabla1[[#This Row],[dimension]],Datos!$B$2:$C$6,2,0),"dim") -> DI | J14: =IFERROR(VLOOKUP(Tabla1[[#This Row],[subdimension]],Datos!$E$2:$F$20,2,0),"subdim") -> DD | K14: =IFERROR(VLOOKUP(Tabla1[[#This Row],[categoria]],Datos!$H$2:$I$21,2,0),"cat") -> cat
B15: =+Tabla1[[#This Row],[dimension_id]]&"_"&Tabla1[[#This Row],[subdimension_id]]&"_"&Tabla1[[#This Row],[categoria_id]] -> DI_DD_cat | C15: Didáctica inclusiva | D15: Didáctica | F15: Asocie los constructos y contenidos teóricos con ejemplos cercanos a la vida de los estudiantes para que puedan ser transferidos a situaciones cotidianas. | G15: Realice ejercicios con un propósito familiar, como ir de compras, que requieran cálculos matemáticos. Especialmente para estudiantes con dificultades de aprendizaje. | H15: =+"Dimensión: " & Tabla1[[#This Row],[dimension]] & " -- " & "Subdimensión: " & Tabla1[[#This Row],[subdimension]] & " -- " & "Categoría: " & Tabla1[[#This Row],[categoria]] & " -- " & Tabla1[[#This Row],[recomendacion]] -> Dimensión: Didáctica inclusiva -- Subdimensión: Didáctica -- Categoría: -- Asocie los constructos y contenidos teóricos con ejemplos cercanos a la vida de los estudiantes para que puedan ser transferidos a situaciones cotidianas. | I15: =IFERROR(VLOOKUP(Tabla1[[#This Row],[dimension]],Datos!$B$2:$C$6,2,0),"dim") -> DI | J15: =IFERROR(VLOOKUP(Tabla1[[#This Row],[subdimension]],Datos!$E$2:$F$20,2,0),"subdim") -> DD | K15: =IFERROR(VLOOKUP(Tabla1[[#This Row],[categoria]],Datos!$H$2:$I$21,2,0),"cat") -> cat
B16: =+Tabla1[[#This Row],[dimension_id]]&"_"&Tabla1[[#This Row],[subdimension_id]]&"_"&Tabla1[[#This Row],[categoria_id]] -> DI_DD_cat | C16: Didáctica inclusiva | D16: Didáctica | F16: Si mejora la comprensión del contenido por parte de los estudiantes, presente el contenido del REA en varios formatos (textos, gráficos, imágenes, etc.). | G16: Si fuera posible, muestre un video, analice el contenido y proporcione actividades prácticas. | H16: =+"Dimensión: " & Tabla1[[#This Row],[dimension]] & " -- " & "Subdimensión: " & Tabla1[[#This Row],[subdimension]] & " -- " & "Categoría: " & Tabla1[[#This Row],[categoria]] & " -- " & Tabla1[[#This Row],[recomendacion]] -> Dimensión: Didáctica inclusiva -- Subdimensión: Didáctica -- Categoría: -- Si mejora la comprensión del contenido por parte de los estudiantes, presente el contenido del REA en varios formatos (textos, gráficos, imágenes, etc.). | I16: =IFERROR(VLOOKUP(Tabla1[[#This Row],[dimension]],Datos!$B$2:$C$6,2,0),"dim") -> DI | J16: =IFERROR(VLOOKUP(Tabla1[[#This Row],[subdimension]],Datos!$E$2:$F$20,2,0),"subdim") -> DD | K16: =IFERROR(VLOOKUP(Tabla1[[#This Row],[categoria]],Datos!$H$2:$I$21,2,0),"cat") -> cat
B17: =+Tabla1[[#This Row],[dimension_id]]&"_"&Tabla1[[#This Row],[subdimension_id]]&"_"&Tabla1[[#This Row],[categoria_id]] -> DI_DD_cat | C17: Didáctica inclusiva | D17: Didáctica | F17: Personalice los REA según el entorno de vida de sus estudiantes. | G17: Si un REA incluye una lectura sobre agricultura que menciona cultivos como el trigo o el maíz, pero sus estudiantes viven en una región donde predominan los olivos y los viñedos, podría modificar el recurso para incluir ejemplos de estos cultivos locales. Esto hace que el contenido sea más significativo y aplicable a su realidad. | H17: =+"Dimensión: " & Tabla1[[#This Row],[dimension]] & " -- " & "Subdimensión: " & Tabla1[[#This Row],[subdimension]] & " -- " & "Categoría: " & Tabla1[[#This Row],[categoria]] & " -- " & Tabla1[[#This Row],[recomendacion]] -> Dimensión: Didáctica inclusiva -- Subdimensión: Didáctica -- Categoría: -- Personalice los REA según el entorno de vida de sus estudiantes. | I17: =IFERROR(VLOOKUP(Tabla1[[#This Row],[dimension]],Datos!$B$2:$C$6,2,0),"dim") -> DI | J17: =IFERROR(VLOOKUP(Tabla1[[#This Row],[subdimension]],Datos!$E$2:$F$20,2,0),"subdim") -> DD | K17: =IFERROR(VLOOKUP(Tabla1[[#This Row],[categoria]],Datos!$H$2:$I$21,2,0),"cat") -> cat
B18: =+Tabla1[[#This Row],[dimension_id]]&"_"&Tabla1[[#This Row],[subdimension_id]]&"_"&Tabla1[[#This Row],[categoria_id]] -> DI_PA_cat | C18: Didáctica inclusiva | D18: Participación | F18: Asegúrese de que las actividades de aprendizaje brinden oportunidades de interacción que respalden el aprendizaje activo. | G18: En una actividad de Piensa-En pareja-Comparte, los estudiantes reflexionan sobre una pregunta, la discuten con un compañero y la comparten con la clase. Esto promueve la interacción, el pensamiento crítico y el aprendizaje activo. | H18: =+"Dimensión: " & Tabla1[[#This Row],[dimension]] & " -- " & "Subdimensión: " & Tabla1[[#This Row],[subdimension]] & " -- " & "Categoría: " & Tabla1[[#This Row],[categoria]] & " -- " & Tabla1[[#This Row],[recomendacion]] -> Dimensión: Didáctica inclusiva -- Subdimensión: Participación -- Categoría: -- Asegúrese de que las actividades de aprendizaje brinden oportunidades de interacción que respalden el aprendizaje activo. | I18: =IFERROR(VLOOKUP(Tabla1[[#This Row],[dimension]],Datos!$B$2:$C$6,2,0),"dim") -> DI | J18: =IFERROR(VLOOKUP(Tabla1[[#This Row],[subdimension]],Datos!$E$2:$F$20,2,0),"subdim") -> PA | K18: =IFERROR(VLOOKUP(Tabla1[[#This Row],[categoria]],Datos!$H$2:$I$21,2,0),"cat") -> cat
B19: =+Tabla1[[#This Row],[dimension_id]]&"_"&Tabla1[[#This Row],[subdimension_id]]&"_"&Tabla1[[#This Row],[categoria_id]] -> DI_PA_cat | C19: Didáctica inclusiva | D19: Participación | F19: Cuando sea posible, cree o adapte los REA para promover el trabajo colaborativo. | H19: =+"Dimensión: " & Tabla1[[#This Row],[dimension]] & " -- " & "Subdimensión: " & Tabla1[[#This Row],[subdimension]] & " -- " & "Categoría: " & Tabla1[[#This Row],[categoria]] & " -- " & Tabla1[[#This Row],[recomendacion]] -> Dimensión: Didáctica inclusiva -- Subdimensión: Participación -- Categoría: -- Cuando sea posible, cree o adapte los REA para promover el trabajo colaborativo. | I19: =IFERROR(VLOOKUP(Tabla1[[#This Row],[dimension]],Datos!$B$2:$C$6,2,0),"dim") -> DI | J19: =IFERROR(VLOOKUP(Tabla1[[#This Row],[subdimension]],Datos!$E$2:$F$20,2,0),"subdim") -> PA | K19: =IFERROR(VLOOKUP(Tabla1[[#This Row],[categoria]],Datos!$H$2:$I$21,2,0),"cat") -> cat
B20: =+Tabla1[[#This Row],[dimension_id]]&"_"&Tabla1[[#This Row],[subdimension_id]]&"_"&Tabla1[[#This Row],[categoria_id]] -> DI_PA_cat | C20: Didáctica inclusiva | D20: Participación | F20: Asegúrese de que los REA faciliten la participación de todos los estudiantes, de acuerdo con sus capacidades y habilidades, creando oportunidades de aprendizaje para todos. | H20: =+"Dimensión: " & Tabla1[[#This Row],[dimension]] & " -- " & "Subdimensión: " & Tabla1[[#This Row],[subdimension]] & " -- " & "Categoría: " & Tabla1[[#This Row],[categoria]] & " -- " & Tabla1[[#This Row],[recomendacion]] -> Dimensión: Didáctica inclusiva -- Subdimensión: Participación -- Categoría: -- Asegúrese de que los REA faciliten la participación de todos los estudiantes, de acuerdo con sus capacidades y habilidades, creando oportunidades de aprendizaje para todos. | I20: =IFERROR(VLOOKUP(Tabla1[[#This Row],[dimension]],Datos!$B$2:$C$6,2,0),"dim") -> DI | J20: =IFERROR(VLOOKUP(Tabla1[[#This Row],[subdimension]],Datos!$E$2:$F$20,2,0),"subdim") -> PA | K20: =IFERROR(VLOOKUP(Tabla1[[#This Row],[categoria]],Datos!$H$2:$I$21,2,0),"cat") -> cat
B21: =+Tabla1[[#This Row],[dimension_id]]&"_"&Tabla1[[#This Row],[subdimension_id]]&"_"&Tabla1[[#This Row],[categoria_id]] -> DI_PA_cat | C21: Didáctica inclusiva | D21: Participación | F21: Al planificar actividades de grupo, considere cómo la composición del grupo (más heterogénea o más homogénea) puede permitir el mejor resultado de aprendizaje posible para todos los estudiantes, teniendo en cuenta las competencias académicas y sociales de todos los estudiantes. | H21: =+"Dimensión: " & Tabla1[[#This Row],[dimension]] & " -- " & "Subdimensión: " & Tabla1[[#This Row],[subdimension]] & " -- " & "Categoría: " & Tabla1[[#This Row],[categoria]] & " -- " & Tabla1[[#This Row],[recomendacion]] -> Dimensión: Didáctica inclusiva -- Subdimensión: Participación -- Categoría: -- Al planificar actividades de grupo, considere cómo la composición del grupo (más heterogénea o más homogénea) puede permitir el mejor resultado de aprendizaje posible para todos los estudiantes, teniendo en cuenta las competencias académicas y sociales de todos los estudiantes. | I21: =IFERROR(VLOOKUP(Tabla1[[#This Row],[dimension]],Datos!$B$2:$C$6,2,0),"dim") -> DI | J21: =IFERROR(VLOOKUP(Tabla1[[#This Row],[subdimension]],Datos!$E$2:$F$20,2,0),"subdim") -> PA | K21: =IFERROR(VLOOKUP(Tabla1[[#This Row],[categoria]],Datos!$H$2:$I$21,2,0),"cat") -> cat
B22: =+Tabla1[[#This Row],[dimension_id]]&"_"&Tabla1[[#This Row],[subdimension_id]]&"_"&Tabla1[[#This Row],[categoria_id]] -> DI_RP_cat | C22: Didáctica inclusiva | D22: Relevancia práctica | F22: Cree o utilice REA que también apoyen la adquisición de habilidades blandas, como la cooperación, la toma de decisiones, la resolución de problemas, el pensamiento crítico, el respeto, la comunicación no violenta, el manejo de las emociones y el estrés. | G22: Desarrolle un REA para enseñar a gestionar el estrés o a hablar en público. | H22: =+"Dimensión: " & Tabla1[[#This Row],[dimension]] & " -- " & "Subdimensión: " & Tabla1[[#This Row],[subdimension]] & " -- " & "Categoría: " & Tabla1[[#This Row],[categoria]] & " -- " & Tabla1[[#This Row],[recomendacion]] -> Dimensión: Didáctica inclusiva -- Subdimensión: Relevancia práctica -- Categoría: -- Cree o utilice REA que también apoyen la adquisición de habilidades blandas, como la cooperación, la toma de decisiones, la resolución de problemas, el pensamiento crítico, el respeto, la comunicación no violenta, el manejo de las emociones y el estrés. | I22: =IFERROR(VLOOKUP(Tabla1[[#This Row],[dimension]],Datos!$B$2:$C$6,2,0),"dim") -> DI | J22: =IFERROR(VLOOKUP(Tabla1[[#This Row],[subdimension]],Datos!$E$2:$F$20,2,0),"subdim") -> RP | K22: =IFERROR(VLOOKUP(Tabla1[[#This Row],[categoria]],Datos!$H$2:$I$21,2,0),"cat") -> cat
B23: =+Tabla1[[#This Row],[dimension_id]]&"_"&Tabla1[[#This Row],[subdimension_id]]&"_"&Tabla1[[#This Row],[categoria_id]] -> DI_RR_cat | C23: Didáctica inclusiva | D23: Relevancia en la vida real | F23: Cuando sea posible, cree o utilice REA que promuevan estilos de vida saludables, como la nutrición, la salud mental y la higiene del sueño. | H23: =+"Dimensión: " & Tabla1[[#This Row],[dimension]] & " -- " & "Subdimensión: " & Tabla1[[#This Row],[subdimension]] & " -- " & "Categoría: " & Tabla1[[#This Row],[categoria]] & " -- " & Tabla1[[#This Row],[recomendacion]] -> Dimensión: Didáctica inclusiva -- Subdimensión: Relevancia en la vida real -- Categoría: -- Cuando sea posible, cree o utilice REA que promuevan estilos de vida saludables, como la nutrición, la salud mental y la higiene del sueño. | I23: =IFERROR(VLOOKUP(Tabla1[[#This Row],[dimension]],Datos!$B$2:$C$6,2,0),"dim") -> DI | J23: =IFERROR(VLOOKUP(Tabla1[[#This Row],[subdimension]],Datos!$E$2:$F$20,2,0),"subdim") -> RR | K23: =IFERROR(VLOOKUP(Tabla1[[#This Row],[categoria]],Datos!$H$2:$I$21,2,0),"cat") -> cat
B24: =+Tabla1[[#This Row],[dimension_id]]&"_"&Tabla1[[#This Row],[subdimension_id]]&"_"&Tabla1[[#This Row],[categoria_id]] -> DI_MO_cat | C24: Didáctica inclusiva | D24: Motivación | F24: Asegúrese de que el REA sea atractivo, interesante y llamativo, ya que puede tener un impacto positivo en la motivación de los estudiantes. | H24: =+"Dimensión: " & Tabla1[[#This Row],[dimension]] & " -- " & "Subdimensión: " & Tabla1[[#This Row],[subdimension]] & " -- " & "Categoría: " & Tabla1[[#This Row],[categoria]] & " -- " & Tabla1[[#This Row],[recomendacion]] -> Dimensión: Didáctica inclusiva -- Subdimensión: Motivación -- Categoría: -- Asegúrese de que el REA sea atractivo, interesante y llamativo, ya que puede tener un impacto positivo en la motivación de los estudiantes. | I24: =IFERROR(VLOOKUP(Tabla1[[#This Row],[dimension]],Datos!$B$2:$C$6,2,0),"dim") -> DI | J24: =IFERROR(VLOOKUP(Tabla1[[#This Row],[subdimension]],Datos!$E$2:$F$20,2,0),"subdim") -> MO | K24: =IFERROR(VLOOKUP(Tabla1[[#This Row],[categoria]],Datos!$H$2:$I$21,2,0),"cat") -> cat
B25: =+Tabla1[[#This Row],[dimension_id]]&"_"&Tabla1[[#This Row],[subdimension_id]]&"_"&Tabla1[[#This Row],[categoria_id]] -> DI_MO_cat | C25: Didáctica inclusiva | D25: Motivación | F25: Asegúrese de que los REA capten y mantengan la atención y el interés de los estudiantes. | G25: Utilice el humor (si es apropiado), utilice ejemplos de la vida diaria de los estudiantes, permita el aprendizaje lúdico, incluya los pasatiempos e intereses de los estudiantes, etc. | H25: =+"Dimensión: " & Tabla1[[#This Row],[dimension]] & " -- " & "Subdimensión: " & Tabla1[[#This Row],[subdimension]] & " -- " & "Categoría: " & Tabla1[[#This Row],[categoria]] & " -- " & Tabla1[[#This Row],[recomendacion]] -> Dimensión: Didáctica inclusiva -- Subdimensión: Motivación -- Categoría: -- Asegúrese de que los REA capten y mantengan la atención y el interés de los estudiantes. | I25: =IFERROR(VLOOKUP(Tabla1[[#This Row],[dimension]],Datos!$B$2:$C$6,2,0),"dim") -> DI | J25: =IFERROR(VLOOKUP(Tabla1[[#This Row],[subdimension]],Datos!$E$2:$F$20,2,0),"subdim") -> MO | K25: =IFERROR(VLOOKUP(Tabla1[[#This Row],[categoria]],Datos!$H$2:$I$21,2,0),"cat") -> cat
B26: =+Tabla1[[#This Row],[dimension_id]]&"_"&Tabla1[[#This Row],[subdimension_id]]&"_"&Tabla1[[#This Row],[categoria_id]] -> DI_EF_cat | C26: Didáctica inclusiva | D26: Evaluación formativa | F26: Incluya observación formativa y evaluación sumativa para asegurarse de poder seguir el proceso de aprendizaje de los estudiantes. | G26: Los estudiantes ven un video sobre el ciclo del agua. El profesor observa las discusiones (formativas) y asigna un breve cuestionario (sumativo) para comprobar la comprensión. | H26: =+"Dimensión: " & Tabla1[[#This Row],[dimension]] & " -- " & "Subdimensión: " & Tabla1[[#This Row],[subdimension]] & " -- " & "Categoría: " & Tabla1[[#This Row],[categoria]] & " -- " & Tabla1[[#This Row],[recomendacion]] -> Dimensión: Didáctica inclusiva -- Subdimensión: Evaluación formativa -- Categoría: -- Incluya observación formativa y evaluación sumativa para asegurarse de poder seguir el proceso de aprendizaje de los estudiantes. | I26: =IFERROR(VLOOKUP(Tabla1[[#This Row],[dimension]],Datos!$B$2:$C$6,2,0),"dim") -> DI | J26: =IFERROR(VLOOKUP(Tabla1[[#This Row],[subdimension]],Datos!$E$2:$F$20,2,0),"subdim") -> EF | K26: =IFERROR(VLOOKUP(Tabla1[[#This Row],[categoria]],Datos!$H$2:$I$21,2,0),"cat") -> cat
B27: =+Tabla1[[#This Row],[dimension_id]]&"_"&Tabla1[[#This Row],[subdimension_id]]&"_"&Tabla1[[#This Row],[categoria_id]] -> TT_subdim_AP | C27: Dimensión técnica y tecnológica | E27: Aprendizaje personalizado | F27: Valora si las herramientas tecnológicas empleadas en el REA facilitan la consecución de los objetivos de aprendizaje marcados. | H27: =+"Dimensión: " & Tabla1[[#This Row],[dimension]] & " -- " & "Subdimensión: " & Tabla1[[#This Row],[subdimension]] & " -- " & "Categoría: " & Tabla1[[#This Row],[categoria]] & " -- " & Tabla1[[#This Row],[recomendacion]] -> Dimensión: Dimensión técnica y tecnológica -- Subdimensión: -- Categoría: Aprendizaje personalizado -- Valora si las herramientas tecnológicas empleadas en el REA facilitan la consecución de los objetivos de aprendizaje marcados. | I27: =IFERROR(VLOOKUP(Tabla1[[#This Row],[dimension]],Datos!$B$2:$C$6,2,0),"dim") -> TT | J27: =IFERROR(VLOOKUP(Tabla1[[#This Row],[subdimension]],Datos!$E$2:$F$20,2,0),"subdim") -> subdim | K27: =IFERROR(VLOOKUP(Tabla1[[#This Row],[categoria]],Datos!$H$2:$I$21,2,0),"cat") -> AP
B28: =+Tabla1[[#This Row],[dimension_id]]&"_"&Tabla1[[#This Row],[subdimension_id]]&"_"&Tabla1[[#This Row],[categoria_id]] -> TT_subdim_AP | C28: Dimensión técnica y tecnológica | E28: Aprendizaje personalizado | F28: Asegúrate de que las herramientas tecnológicas y recursos empleados en los REA fomentan la participación del alumnado y el aprendizaje activo. | G28: Usa foros, herramientas de aprendizaje colaborativo, herramientas de autoevaluación, etc. | H28: =+"Dimensión: " & Tabla1[[#This Row],[dimension]] & " -- " & "Subdimensión: " & Tabla1[[#This Row],[subdimension]] & " -- " & "Categoría: " & Tabla1[[#This Row],[categoria]] & " -- " & Tabla1[[#This Row],[recomendacion]] -> Dimensión: Dimensión técnica y tecnológica -- Subdimensión: -- Categoría: Aprendizaje personalizado -- Asegúrate de que las herramientas tecnológicas y recursos empleados en los REA fomentan la participación del alumnado y el aprendizaje activo. | I28: =IFERROR(VLOOKUP(Tabla1[[#This Row],[dimension]],Datos!$B$2:$C$6,2,0),"dim") -> TT | J28: =IFERROR(VLOOKUP(Tabla1[[#This Row],[subdimension]],Datos!$E$2:$F$20,2,0),"subdim") -> subdim | K28: =IFERROR(VLOOKUP(Tabla1[[#This Row],[categoria]],Datos!$H$2:$I$21,2,0),"cat") -> AP
B29: =+Tabla1[[#This Row],[dimension_id]]&"_"&Tabla1[[#This Row],[subdimension_id]]&"_"&Tabla1[[#This Row],[categoria_id]] -> TT_subdim_AP | C29: Dimensión técnica y tecnológica | E29: Aprendizaje personalizado | F29: Comprueba que todo el alumnado tenga acceso a los medios tecnológicos requeridos para consultar el REA. | G29: Cerciórate de que los alumnos disponen de ordenador, acceso a internet o una impresora. | H29: =+"Dimensión: " & Tabla1[[#This Row],[dimension]] & " -- " & "Subdimensión: " & Tabla1[[#This Row],[subdimension]] & " -- " & "Categoría: " & Tabla1[[#This Row],[categoria]] & " -- " & Tabla1[[#This Row],[recomendacion]] -> Dimensión: Dimensión técnica y tecnológica -- Subdimensión: -- Categoría: Aprendizaje personalizado -- Comprueba que todo el alumnado tenga acceso a los medios tecnológicos requeridos para consultar el REA. | I29: =IFERROR(VLOOKUP(Tabla1[[#This Row],[dimension]],Datos!$B$2:$C$6,2,0),"dim") -> TT | J29: =IFERROR(VLOOKUP(Tabla1[[#This Row],[subdimension]],Datos!$E$2:$F$20,2,0),"subdim") -> subdim | K29: =IFERROR(VLOOKUP(Tabla1[[#This Row],[categoria]],Datos!$H$2:$I$21,2,0),"cat") -> AP
B30: =+Tabla1[[#This Row],[dimension_id]]&"_"&Tabla1[[#This Row],[subdimension_id]]&"_"&Tabla1[[#This Row],[categoria_id]] -> TT_subdim_AP | C30: Dimensión técnica y tecnológica | E30: Aprendizaje personalizado | F30: Garantiza que los estudiantes con necesidades especiales también tengan acceso a los medios tecnológicos requeridos para usar el REA. | G30: Comprueba que el alumnado con discapacidad visual cuenta con un lector de pantalla o proporciona un ratón ergonómico para estudiantes con movilidad reducida. | H30: =+"Dimensión: " & Tabla1[[#This Row],[dimension]] & " -- " & "Subdimensión: " & Tabla1[[#This Row],[subdimension]] & " -- " & "Categoría: " & Tabla1[[#This Row],[categoria]] & " -- " & Tabla1[[#This Row],[recomendacion]] -> Dimensión: Dimensión técnica y tecnológica -- Subdimensión: -- Categoría: Aprendizaje personalizado -- Garantiza que los estudiantes con necesidades especiales también tengan acceso a los medios tecnológicos requeridos para usar el REA. | I30: =IFERROR(VLOOKUP(Tabla1[[#This Row],[dimension]],Datos!$B$2:$C$6,2,0),"dim") -> TT | J30: =IFERROR(VLOOKUP(Tabla1[[#This Row],[subdimension]],Datos!$E$2:$F$20,2,0),"subdim") -> subdim | K30: =IFERROR(VLOOKUP(Tabla1[[#This Row],[categoria]],Datos!$H$2:$I$21,2,0),"cat") -> AP
B31: =+Tabla1[[#This Row],[dimension_id]]&"_"&Tabla1[[#This Row],[subdimension_id]]&"_"&Tabla1[[#This Row],[categoria_id]] -> TT_subdim_ADP | C31: Dimensión técnica y tecnológica | E31: Adaptabilidad | F31: Diseña REA que se puedan utilizar en diferentes contextos educativos: en clase, en ordenadores o en otros dispositivos (como tabletas o pizarras electrónicas), sistemas de e-learning, etc. Asegúrate de que el REA pueda ser modificado, actualizado o adaptado en función de los intereses y necesidades del alumnado. | G31: Facilita el REA en un formato editable (p. ej.: Word), en un archivo de texto plano o proporciona el código fuente para que pueda ser modificado. | H31: =+"Dimensión: " & Tabla1[[#This Row],[dimension]] & " -- " & "Subdimensión: " & Tabla1[[#This Row],[subdimension]] & " -- " & "Categoría: " & Tabla1[[#This Row],[categoria]] & " -- " & Tabla1[[#This Row],[recomendacion]] -> Dimensión: Dimensión técnica y tecnológica -- Subdimensión: -- Categoría: Adaptabilidad -- Diseña REA que se puedan utilizar en diferentes contextos educativos: en clase, en ordenadores o en otros dispositivos (como tabletas o pizarras electrónicas), sistemas de e-learning, etc. Asegúrate de que el REA pueda ser modificado, actualizado o adaptado en función de los intereses y necesidades del alumnado. | I31: =IFERROR(VLOOKUP(Tabla1[[#This Row],[dimension]],Datos!$B$2:$C$6,2,0),"dim") -> TT | J31: =IFERROR(VLOOKUP(Tabla1[[#This Row],[subdimension]],Datos!$E$2:$F$20,2,0),"subdim") -> subdim | K31: =IFERROR(VLOOKUP(Tabla1[[#This Row],[categoria]],Datos!$H$2:$I$21,2,0),"cat") -> ADP
B32: =+Tabla1[[#This Row],[dimension_id]]&"_"&Tabla1[[#This Row],[subdimension_id]]&"_"&Tabla1[[#This Row],[categoria_id]] -> TT_subdim_SEG | C32: Dimensión técnica y tecnológica | E32: Seguridad | F32: Desarrolla el REA teniendo en cuenta todas las medidas posibles para garantizar la seguridad, la integridad y validez de la información. | G32: Utiliza protección por contraseña, encriptación, plataformas seguras, sistemas de gestión del aprendizaje, etc. | H32: =+"Dimensión: " & Tabla1[[#This Row],[dimension]] & " -- " & "Subdimensión: " & Tabla1[[#This Row],[subdimension]] & " -- " & "Categoría: " & Tabla1[[#This Row],[categoria]] & " -- " & Tabla1[[#This Row],[recomendacion]] -> Dimensión: Dimensión técnica y tecnológica -- Subdimensión: -- Categoría: Seguridad -- Desarrolla el REA teniendo en cuenta todas las medidas posibles para garantizar la seguridad, la integridad y validez de la información. | I32: =IFERROR(VLOOKUP(Tabla1[[#This Row],[dimension]],Datos!$B$2:$C$6,2,0),"dim") -> TT | J32: =IFERROR(VLOOKUP(Tabla1[[#This Row],[subdimension]],Datos!$E$2:$F$20,2,0),"subdim") -> subdim | K32: =IFERROR(VLOOKUP(Tabla1[[#This Row],[categoria]],Datos!$H$2:$I$21,2,0),"cat") -> SEG
B33: =+Tabla1[[#This Row],[dimension_id]]&"_"&Tabla1[[#This Row],[subdimension_id]]&"_"&Tabla1[[#This Row],[categoria_id]] -> TT_subdim_AYU | C33: Dimensión técnica y tecnológica | E33: Ayuda | F33: Garantiza la disponibilidad de enlaces o explicaciones sobre asistencia técnica en el REA. | G33: Ofrece sugerencias de solución a posibles problemas técnicos o enlaces a asistencia técnica. | H33: =+"Dimensión: " & Tabla1[[#This Row],[dimension]] & " -- " & "Subdimensión: " & Tabla1[[#This Row],[subdimension]] & " -- " & "Categoría: " & Tabla1[[#This Row],[categoria]] & " -- " & Tabla1[[#This Row],[recomendacion]] -> Dimensión: Dimensión técnica y tecnológica -- Subdimensión: -- Categoría: Ayuda -- Garantiza la disponibilidad de enlaces o explicaciones sobre asistencia técnica en el REA. | I33: =IFERROR(VLOOKUP(Tabla1[[#This Row],[dimension]],Datos!$B$2:$C$6,2,0),"dim") -> TT | J33: =IFERROR(VLOOKUP(Tabla1[[#This Row],[subdimension]],Datos!$E$2:$F$20,2,0),"subdim") -> subdim | K33: =IFERROR(VLOOKUP(Tabla1[[#This Row],[categoria]],Datos!$H$2:$I$21,2,0),"cat") -> AYU
B34: =+Tabla1[[#This Row],[dimension_id]]&"_"&Tabla1[[#This Row],[subdimension_id]]&"_"&Tabla1[[#This Row],[categoria_id]] -> TT_subdim_AYU | C34: Dimensión técnica y tecnológica | E34: Ayuda | F34: Comprueba la disponibilidad de funciones de ayuda que identifiquen los problemas más comunes de los usuarios y sus soluciones. | G34: Asegúrate de que la interfaz de usuario disponga de mecanismos (p. ej., preguntas frecuentes o documentación de ayuda) para que los usuarios puedan solucionar los problemas que surjan en el uso del REA. Además, la ayuda debe ser fácil de localizar, especificar los pasos necesarios para resolver el problema y no ser muy extensa. | H34: =+"Dimensión: " & Tabla1[[#This Row],[dimension]] & " -- " & "Subdimensión: " & Tabla1[[#This Row],[subdimension]] & " -- " & "Categoría: " & Tabla1[[#This Row],[categoria]] & " -- " & Tabla1[[#This Row],[recomendacion]] -> Dimensión: Dimensión técnica y tecnológica -- Subdimensión: -- Categoría: Ayuda -- Comprueba la disponibilidad de funciones de ayuda que identifiquen los problemas más comunes de los usuarios y sus soluciones. | I34: =IFERROR(VLOOKUP(Tabla1[[#This Row],[dimension]],Datos!$B$2:$C$6,2,0),"dim") -> TT | J34: =IFERROR(VLOOKUP(Tabla1[[#This Row],[subdimension]],Datos!$E$2:$F$20,2,0),"subdim") -> subdim | K34: =IFERROR(VLOOKUP(Tabla1[[#This Row],[categoria]],Datos!$H$2:$I$21,2,0),"cat") -> AYU
B35: =+Tabla1[[#This Row],[dimension_id]]&"_"&Tabla1[[#This Row],[subdimension_id]]&"_"&Tabla1[[#This Row],[categoria_id]] -> TT_US_DIS | C35: Dimensión técnica y tecnológica | D35: Usabilidad | E35: Diseño | F35: Garantiza que el diseño visual de la interfaz de usuario sea claro y coherente para facilitar el aprendizaje. Evita el ruido visual y la sobrecarga de información. | G35: Emplea títulos breves, una fuente legible, justificación a la izquierda, colores equilibrados, etc. Evita elementos de distracción como colores irrelevantes o figuras e iconos con una función meramente ornamental. | H35: =+"Dimensión: " & Tabla1[[#This Row],[dimension]] & " -- " & "Subdimensión: " & Tabla1[[#This Row],[subdimension]] & " -- " & "Categoría: " & Tabla1[[#This Row],[categoria]] & " -- " & Tabla1[[#This Row],[recomendacion]] -> Dimensión: Dimensión técnica y tecnológica -- Subdimensión: Usabilidad -- Categoría: Diseño -- Garantiza que el diseño visual de la interfaz de usuario sea claro y coherente para facilitar el aprendizaje. Evita el ruido visual y la sobrecarga de información. | I35: =IFERROR(VLOOKUP(Tabla1[[#This Row],[dimension]],Datos!$B$2:$C$6,2,0),"dim") -> TT | J35: =IFERROR(VLOOKUP(Tabla1[[#This Row],[subdimension]],Datos!$E$2:$F$20,2,0),"subdim") -> US | K35: =IFERROR(VLOOKUP(Tabla1[[#This Row],[categoria]],Datos!$H$2:$I$21,2,0),"cat") -> DIS
B36: =+Tabla1[[#This Row],[dimension_id]]&"_"&Tabla1[[#This Row],[subdimension_id]]&"_"&Tabla1[[#This Row],[categoria_id]] -> TT_US_DIS | C36: Dimensión técnica y tecnológica | D36: Usabilidad | E36: Diseño | F36: Asegúrate de que el diseño del REA sea intuitivo. | G36: Parte de un diseño visual al que los usuarios estén habituados. Por ejemplo, utiliza iconos o imágenes de función inequívoca (p. ej.: una papelera como icono de eliminación). | H36: =+"Dimensión: " & Tabla1[[#This Row],[dimension]] & " -- " & "Subdimensión: " & Tabla1[[#This Row],[subdimension]] & " -- " & "Categoría: " & Tabla1[[#This Row],[categoria]] & " -- " & Tabla1[[#This Row],[recomendacion]] -> Dimensión: Dimensión técnica y tecnológica -- Subdimensión: Usabilidad -- Categoría: Diseño -- Asegúrate de que el diseño del REA sea intuitivo. | I36: =IFERROR(VLOOKUP(Tabla1[[#This Row],[dimension]],Datos!$B$2:$C$6,2,0),"dim") -> TT | J36: =IFERROR(VLOOKUP(Tabla1[[#This Row],[subdimension]],Datos!$E$2:$F$20,2,0),"subdim") -> US | K36: =IFERROR(VLOOKUP(Tabla1[[#This Row],[categoria]],Datos!$H$2:$I$21,2,0),"cat") -> DIS
B37: =+Tabla1[[#This Row],[dimension_id]]&"_"&Tabla1[[#This Row],[subdimension_id]]&"_"&Tabla1[[#This Row],[categoria_id]] -> TT_US_PER | C37: Dimensión técnica y tecnológica | D37: Usabilidad | E37: Personalización | F37: Comprueba que el usuario pueda personalizar la interfaz (p. ej., cambiar el color de fondo o aumentar el contraste) para mejorar la legibilidad y la usabilidad del REA. | G37: Escoge colores oscuros para el texto y colores claros para el fondo. Puedes verificar que el contraste de colores sea el adecuado con herramientas como Color Contrast Analyzer. | H37: =+"Dimensión: " & Tabla1[[#This Row],[dimension]] & " -- " & "Subdimensión: " & Tabla1[[#This Row],[subdimension]] & " -- " & "Categoría: " & Tabla1[[#This Row],[categoria]] & " -- " & Tabla1[[#This Row],[recomendacion]] -> Dimensión: Dimensión técnica y tecnológica -- Subdimensión: Usabilidad -- Categoría: Personalización -- Comprueba que el usuario pueda personalizar la interfaz (p. ej., cambiar el color de fondo o aumentar el contraste) para mejorar la legibilidad y la usabilidad del REA. | I37: =IFERROR(VLOOKUP(Tabla1[[#This Row],[dimension]],Datos!$B$2:$C$6,2,0),"dim") -> TT | J37: =IFERROR(VLOOKUP(Tabla1[[#This Row],[subdimension]],Datos!$E$2:$F$20,2,0),"subdim") -> US | K37: =IFERROR(VLOOKUP(Tabla1[[#This Row],[categoria]],Datos!$H$2:$I$21,2,0),"cat") -> PER
B38: =+Tabla1[[#This Row],[dimension_id]]&"_"&Tabla1[[#This Row],[subdimension_id]]&"_"&Tabla1[[#This Row],[categoria_id]] -> TT_US_FUE | C38: Dimensión técnica y tecnológica | D38: Usabilidad | E38: Fuente | F38: Revisa que las fuentes empleadas sean legibles y visualmente atractivas o facilita que el usuario cambie el tipo de fuente, el color y el tamaño. | G38: Usa Times New Roman, Georgia, Arial, Calibri, Verdana o Tahoma. Si bien el tamaño mínimo es 10, se recomienda aumentarlo a 12 o 14 para estudiantes con discapacidad visual o dificultades de lectoescritura. | H38: =+"Dimensión: " & Tabla1[[#This Row],[dimension]] & " -- " & "Subdimensión: " & Tabla1[[#This Row],[subdimension]] & " -- " & "Categoría: " & Tabla1[[#This Row],[categoria]] & " -- " & Tabla1[[#This Row],[recomendacion]] -> Dimensión: Dimensión técnica y tecnológica -- Subdimensión: Usabilidad -- Categoría: Fuente -- Revisa que las fuentes empleadas sean legibles y visualmente atractivas o facilita que el usuario cambie el tipo de fuente, el color y el tamaño. | I38: =IFERROR(VLOOKUP(Tabla1[[#This Row],[dimension]],Datos!$B$2:$C$6,2,0),"dim") -> TT | J38: =IFERROR(VLOOKUP(Tabla1[[#This Row],[subdimension]],Datos!$E$2:$F$20,2,0),"subdim") -> US | K38: =IFERROR(VLOOKUP(Tabla1[[#This Row],[categoria]],Datos!$H$2:$I$21,2,0),"cat") -> FUE
B39: =+Tabla1[[#This Row],[dimension_id]]&"_"&Tabla1[[#This Row],[subdimension_id]]&"_"&Tabla1[[#This Row],[categoria_id]] -> TT_US_DIS | C39: Dimensión técnica y tecnológica | D39: Usabilidad | E39: Diseño y formato | F39: Verifica que el diseño de la interfaz refleje la información correctamente jerarquizada. | G39: Diseña los elementos de la interfaz (títulos, botones, enlaces, menús, etc.) de manera que sea comprensible y de fácil navegación. | H39: =+"Dimensión: " & Tabla1[[#This Row],[dimension]] & " -- " & "Subdimensión: " & Tabla1[[#This Row],[subdimension]] & " -- " & "Categoría: " & Tabla1[[#This Row],[categoria]] & " -- " & Tabla1[[#This Row],[recomendacion]] -> Dimensión: Dimensión técnica y tecnológica -- Subdimensión: Usabilidad -- Categoría: Diseño y formato -- Verifica que el diseño de la interfaz refleje la información correctamente jerarquizada. | I39: =IFERROR(VLOOKUP(Tabla1[[#This Row],[dimension]],Datos!$B$2:$C$6,2,0),"dim") -> TT | J39: =IFERROR(VLOOKUP(Tabla1[[#This Row],[subdimension]],Datos!$E$2:$F$20,2,0),"subdim") -> US | K39: =IFERROR(VLOOKUP(Tabla1[[#This Row],[categoria]],Datos!$H$2:$I$21,2,0),"cat") -> DIS
B40: =+Tabla1[[#This Row],[dimension_id]]&"_"&Tabla1[[#This Row],[subdimension_id]]&"_"&Tabla1[[#This Row],[categoria_id]] -> TT_US_NAV | C40: Dimensión técnica y tecnológica | D40: Usabilidad | E40: Navegación | F40: Comprueba que la navegación es previsible y eficaz. | G40: Elige nombres descriptivos para los elementos de navegación y emplea un diseño visual que los diferencie claramente de los demás elementos de la interfaz. | H40: =+"Dimensión: " & Tabla1[[#This Row],[dimension]] & " -- " & "Subdimensión: " & Tabla1[[#This Row],[subdimension]] & " -- " & "Categoría: " & Tabla1[[#This Row],[categoria]] & " -- " & Tabla1[[#This Row],[recomendacion]] -> Dimensión: Dimensión técnica y tecnológica -- Subdimensión: Usabilidad -- Categoría: Navegación -- Comprueba que la navegación es previsible y eficaz. | I40: =IFERROR(VLOOKUP(Tabla1[[#This Row],[dimension]],Datos!$B$2:$C$6,2,0),"dim") -> TT | J40: =IFERROR(VLOOKUP(Tabla1[[#This Row],[subdimension]],Datos!$E$2:$F$20,2,0),"subdim") -> US | K40: =IFERROR(VLOOKUP(Tabla1[[#This Row],[categoria]],Datos!$H$2:$I$21,2,0),"cat") -> NAV
B41: =+Tabla1[[#This Row],[dimension_id]]&"_"&Tabla1[[#This Row],[subdimension_id]]&"_"&Tabla1[[#This Row],[categoria_id]] -> TT_US_NAV | C41: Dimensión técnica y tecnológica | D41: Usabilidad | E41: Navegación | F41: Asegúrate de que la navegación sigue un orden lógico. | G41: Ordena de forma lógica los elementos de navegación (enlaces, barras de navegación, menús, etc.) y verifica que se mantengan siempre en la misma ubicación. Por ejemplo, las barras de navegación se pueden colocar en la parte superior o inferior de la pantalla. Respeta el número de elementos recomendados en un menú de navegación: entre 6 y 8. | H41: =+"Dimensión: " & Tabla1[[#This Row],[dimension]] & " -- " & "Subdimensión: " & Tabla1[[#This Row],[subdimension]] & " -- " & "Categoría: " & Tabla1[[#This Row],[categoria]] & " -- " & Tabla1[[#This Row],[recomendacion]] -> Dimensión: Dimensión técnica y tecnológica -- Subdimensión: Usabilidad -- Categoría: Navegación -- Asegúrate de que la navegación sigue un orden lógico. | I41: =IFERROR(VLOOKUP(Tabla1[[#This Row],[dimension]],Datos!$B$2:$C$6,2,0),"dim") -> TT | J41: =IFERROR(VLOOKUP(Tabla1[[#This Row],[subdimension]],Datos!$E$2:$F$20,2,0),"subdim") -> US | K41: =IFERROR(VLOOKUP(Tabla1[[#This Row],[categoria]],Datos!$H$2:$I$21,2,0),"cat") -> NAV
...

Sheet Datos
B2: dimension | C2: id | E2: subdimension | F2: id | H2: categoria | I2: id
B3: Didáctica inclusiva | C3: DI | E3: Objetivos y metas | F3: OM | H3: Aprendizaje personalizado | I3: AP
B4: Dimensión técnica y tecnológica | C4: TT | E4: Objetivos de aprendizaje para la enseñanza diferenciada | F4: OA | H4: Adaptabilidad | I4: ADP
B5: Sensibilidad hacia la diversidad | C5: SD | E5: Metadatos | F5: MD | H5: Seguridad | I5: SEG
B6: Accesibilidad | C6: AC | E6: Idioma | F6: IDI | H6: Ayuda | I6: AYU
E7: Actualización | F7: CT | H7: Diseño | I7: DIS
E8: Estructura | F8: ES | H8: Personalización | I8: PER
E9: Didáctica | F9: DD | H9: Fuente | I9: FUE
E10: Participación | F10: PA | H10: Diseño y formato | I10: DIS
E11: Relevancia práctica | F11: RP | H11: Navegación | I11: NAV
E12: Relevancia en la vida real | F12: RR | H12: Uso de los REA | I12: USO
E13: Motivación | F13: MO | H13: Desarrollo de los REA | I13: DES
E14: Evaluación formativa | F14: EF | H14: Elección de los metadatos | I14: ELE
E15: Usabilidad | F15: US | H15: Adaptación de los REA | I15: ADA
E16: Licencias | F16: LI | H16: Texto | I16: TEX
E17: Conciencia de género | F17: CG | H17: Imágenes, tablas y gráficos | I17: IMA
E18: Sensibilidad cultural | F18: SC | H18: Audio | I18: AUD
... E20: Accesibilidad tecnológica | F20: AT | H20: Sitios web y apps | I20: WEB
H21: Juegos educativos | I21: JUE
